<?xml version="1.0" encoding="utf-8" ?>
<!-- This URDF was automatically created by SolidWorks to URDF Exporter! Originally created by Stephen Brawner (brawner@gmail.com)
     Commit Version: 1.6.0-1-g15f4949  Build Version: 1.6.7594.29634
     For more information, please see http:/wiki.ros.org/sw_urdf_exporter -->
<robot name="nova2_robot">
    <link name="dummy_link" />
    <link name="base_link">
        <inertial>
            <origin xyz="1.31739324853774E-05 -7.84959718585273E-06 0.0647773077977383" rpy="0 0 0" />
            <mass value="0.939873286768969" />
            <inertia ixx="0.00191682867137382" ixy="-3.45738044468349E-07" ixz="7.09345652971545E-07" iyy="0.00192279468074328" iyz="-4.56838232777704E-07" izz="0.00127269960160789" />
        </inertial>
        <visual>
            <origin xyz="0 0 0" rpy="0 0 0" />
            <geometry>
                <mesh filename="package://dobot_description/meshes/nova2/base_link.STL" />
            </geometry>
            <material name="">
                <color rgba="0.792156862745098 0.819607843137255 0.933333333333333 1" />
            </material>
        </visual>
        <collision>
            <origin xyz="0 0 0" rpy="0 0 0" />
            <geometry>
                <mesh filename="package://dobot_description/meshes/nova2/base_link.STL" />
            </geometry>
        </collision>
    </link>
    <joint name="dummy_joint" type="fixed">
        <parent link="dummy_link" />
        <child link="base_link" />
    </joint>
    <link name="Link1">
        <inertial>
            <origin xyz="-5.44523391156536E-07 -0.0218722568945782 -0.0236239644661121" rpy="0 0 0" />
            <mass value="0.803371401390743" />
            <inertia ixx="0.00167952903521413" ixy="1.54449368288654E-07" ixz="6.95728401748556E-08" iyy="0.00146965832921226" iyz="0.000442022256560709" izz="0.00103706598237737" />
        </inertial>
        <visual>
            <origin xyz="0 0 0" rpy="0 0 0" />
            <geometry>
                <mesh filename="package://dobot_description/meshes/nova2/Link1.STL" />
            </geometry>
            <material name="">
                <color rgba="0.792156862745098 0.819607843137255 0.933333333333333 1" />
            </material>
        </visual>
        <collision>
            <origin xyz="0 0 0" rpy="0 0 0" />
            <geometry>
                <mesh filename="package://dobot_description/meshes/nova2/Link1.STL" />
            </geometry>
        </collision>
    </link>
    <joint name="joint1" type="revolute">
        <origin xyz="0 0 0.2234" rpy="0 0 0" />
        <parent link="base_link" />
        <child link="Link1" />
        <axis xyz="0 0 1" />
        <limit lower="-6.28" upper="6.28" effort="0" velocity="0" />
    </joint>
    <link name="Link2">
        <inertial>
            <origin xyz="-0.150313750410422 4.18877523206172E-06 0.0931448460647906" rpy="0 0 0" />
            <mass value="1.57815975340995" />
            <inertia ixx="0.00156674973214016" ixy="-1.57289561886805E-07" ixz="-0.00115240117121709" iyy="0.0216397042193888" iyz="-1.09920891390281E-07" izz="0.0217363605210336" />
        </inertial>
        <visual>
            <origin xyz="0 0 0" rpy="0 0 0" />
            <geometry>
                <mesh filename="package://dobot_description/meshes/nova2/Link2.STL" />
            </geometry>
            <material name="">
                <color rgba="0.792156862745098 0.819607843137255 0.933333333333333 1" />
            </material>
        </visual>
        <collision>
            <origin xyz="0 0 0" rpy="0 0 0" />
            <geometry>
                <mesh filename="package://dobot_description/meshes/nova2/Link2.STL" />
            </geometry>
        </collision>
    </link>
    <joint name="joint2" type="revolute">
        <origin xyz="0 0 0" rpy="1.5708 1.5708 0" />
        <parent link="Link1" />
        <child link="Link2" />
        <axis xyz="0 0 1" />
        <limit lower="-3.14" upper="3.14" effort="0" velocity="0" />
    </joint>
    <link name="Link3">
        <inertial>
            <origin xyz="-0.118295307270688 3.91200533585901E-06 0.0113008075933966" rpy="0 0 0" />
            <mass value="0.99867391089996" />
            <inertia ixx="0.000775712315283709" ixy="4.7133171421654E-08" ixz="0.000543588636158171" iyy="0.00938204904571472" iyz="6.82619728416736E-08" izz="0.00940115973618697" />
        </inertial>
        <visual>
            <origin xyz="0 0 0" rpy="0 0 0" />
            <geometry>
                <mesh filename="package://dobot_description/meshes/nova2/Link3.STL" />
            </geometry>
            <material name="">
                <color rgba="0.792156862745098 0.819607843137255 0.933333333333333 1" />
            </material>
        </visual>
        <collision>
            <origin xyz="0 0 0" rpy="0 0 0" />
            <geometry>
                <mesh filename="package://dobot_description/meshes/nova2/Link3.STL" />
            </geometry>
        </collision>
    </link>
    <joint name="joint3" type="revolute">
        <origin xyz="-0.28 0 0" rpy="0 0 0" />
        <parent link="Link2" />
        <child link="Link3" />
        <axis xyz="0 0 1" />
        <limit lower="-2.79" upper="2.79" effort="0" velocity="0" />
    </joint>
    <link name="Link4">
        <inertial>
            <origin xyz="-7.47431367277975E-06 -0.0226550273917204 -0.0204586561908531" rpy="0 0 0" />
            <mass value="0.441608812891546" />
            <inertia ixx="0.000641172450255966" ixy="1.23887771284186E-08" ixz="3.02489770721575E-08" iyy="0.000455371502301378" iyz="0.000213282779675717" izz="0.000482718528361731" />
        </inertial>
        <visual>
            <origin xyz="0 0 0" rpy="0 0 0" />
            <geometry>
                <mesh filename="package://dobot_description/meshes/nova2/Link4.STL" />
            </geometry>
            <material name="">
                <color rgba="0.792156862745098 0.819607843137255 0.933333333333333 1" />
            </material>
        </visual>
        <collision>
            <origin xyz="0 0 0" rpy="0 0 0" />
            <geometry>
                <mesh filename="package://dobot_description/meshes/nova2/Link4.STL" />
            </geometry>
        </collision>
    </link>
    <joint name="joint4" type="revolute">
        <origin xyz="-0.22501 0 0.1175" rpy="0 0 -1.5708" />
        <parent link="Link3" />
        <child link="Link4" />
        <axis xyz="0 0 1" />
        <limit lower="-6.28" upper="6.28" effort="0" velocity="0" />
    </joint>
    <link name="Link5">
        <inertial>
            <origin xyz="-2.62723419601498E-06 0.00191303345902123 -0.00761123061599434" rpy="0 0 0" />
            <mass value="0.574835130262751" />
            <inertia ixx="0.000663176880312698" ixy="1.50480808241957E-08" ixz="1.31860791104645E-08" iyy="0.000397520642705227" iyz="-0.000120263783985693" izz="0.000641156755381468" />
        </inertial>
        <visual>
            <origin xyz="0 0 0" rpy="0 0 0" />
            <geometry>
                <mesh filename="package://dobot_description/meshes/nova2/Link5.STL" />
            </geometry>
            <material name="">
                <color rgba="0.792156862745098 0.819607843137255 0.933333333333333 1" />
            </material>
        </visual>
        <collision>
            <origin xyz="0 0 0" rpy="0 0 0" />
            <geometry>
                <mesh filename="package://dobot_description/meshes/nova2/Link5.STL" />
            </geometry>
        </collision>
    </link>
    <joint name="joint5" type="revolute">
        <origin xyz="0 -0.12 0" rpy="1.5708 0 0" />
        <parent link="Link4" />
        <child link="Link5" />
        <axis xyz="0 0 1" />
        <limit lower="-6.28" upper="6.28" effort="0" velocity="0" />
    </joint>
    <link name="Link6">
        <inertial>
            <origin xyz="-4.63325246499096E-07 -4.92709726822582E-05 -0.0196921496196789" rpy="0 0 0" />
            <mass value="0.124247087839584" />
            <inertia ixx="4.97044850239183E-05" ixy="1.38276337649473E-11" ixz="-2.68970069169078E-11" iyy="4.99145981166397E-05" iyz="5.03763611900752E-08" izz="7.67222809720147E-05" />
        </inertial>
        <visual>
            <origin xyz="0 0 0" rpy="0 0 0" />
            <geometry>
                <mesh filename="package://dobot_description/meshes/nova2/Link6.STL" />
            </geometry>
            <material name="">
                <color rgba="0.792156862745098 0.819607843137255 0.933333333333333 1" />
            </material>
        </visual>
        <collision>
            <origin xyz="0 0 0" rpy="0 0 0" />
            <geometry>
                <mesh filename="package://dobot_description/meshes/nova2/Link6.STL" />
            </geometry>
        </collision>
    </link>
    <joint name="joint6" type="revolute">
        <origin xyz="0 0.088004 0" rpy="-1.5708 0 0" />
        <parent link="Link5" />
        <child link="Link6" />
        <axis xyz="0 0 1" />
        <limit lower="-3.13" upper="3.13" effort="0" velocity="0" />
    </joint>
    <link name="hand_base_link">
        <inertial>
            <origin xyz="-3.9257E-06 -0.00027208 0.037806" rpy="0 0 0" />
            <mass value="0.34365" />
            <inertia ixx="0.00036805" ixy="-7.2868E-08" ixz="-5.0168E-08" iyy="0.0003341" iyz="-2.6462E-06" izz="0.00022294" />
        </inertial>
        <visual>
            <origin xyz="0 0 0" rpy="0 0 0" />
            <geometry>
                <mesh filename="package://dobot_description/meshes/nova2/finger/base_link.STL" />
            </geometry>
            <material name="">
                <color rgba="1 1 1 1" />
            </material>
        </visual>
        <collision>
            <origin xyz="0 0 0.05" rpy="0 0 0" />
            <geometry>
                <cylinder length="0.08" radius="0.04"/>
            </geometry>
        </collision>
    </link>
    <joint name="joint7" type="fixed">
        <origin xyz="0.0 0.0 0.0" rpy="0 0 0" />
        <parent link="Link6" />
        <child link="hand_base_link" />
    </joint>
    <link name="finger1_link">
        <inertial>
            <origin xyz="0.0030491 -0.0066024 0.0064209" rpy="0 0 0" />
            <mass value="0.014278" />
            <inertia ixx="1.7567E-06" ixy="-5.7832E-08" ixz="2.6803E-08" iyy="2.3034E-06" iyz="2.2145E-07" izz="1.3354E-06" />
        </inertial>
        <visual>
            <origin xyz="0 0 0" rpy="0 0 0" />
            <geometry>
                <mesh filename="package://dobot_description/meshes/nova2/finger/finger1_Link.STL" />
            </geometry>
            <material name="">
                <color rgba="1 1 1 1" />
            </material>
        </visual>
        <collision>
            <origin xyz="0 0 0.02" rpy="0 0 0" />
            <geometry>
                <cylinder length="0.04" radius="0.01"/>
            </geometry>
        </collision>
    </link>
    <joint name="finger1_joint" type="prismatic">
        <origin xyz="0.0132 0.0265 0.093" rpy="0 0 -1.5708" />
        <parent link="hand_base_link" />
        <child link="finger1_link" />
        <axis xyz="1 0 0" />
        <limit lower="0" upper="0.025" effort="140" velocity="1" />
    </joint>
    <link name="finger2_link">
        <inertial>
            <origin xyz="0.0030491 -0.0066024 0.0064209" rpy="0 0 0" />
            <mass value="0.014278" />
            <inertia ixx="1.7567E-06" ixy="-5.7832E-08" ixz="2.6803E-08" iyy="2.3034E-06" iyz="2.2145E-07" izz="1.3354E-06" />
        </inertial>
        <visual>
            <origin xyz="0 0 0" rpy="0 0 0" />
            <geometry>
                <mesh filename="package://dobot_description/meshes/nova2/finger/finger2_Link.STL" />
            </geometry>
            <material name="">
                <color rgba="0.79216 0.81961 0.93333 1" />
            </material>
        </visual>
        <collision>
            <origin xyz="0 0 0.02" rpy="0 0 0" />
            <geometry>
                <cylinder length="0.04" radius="0.01"/>
            </geometry>
        </collision>
    </link>
    <joint name="finger2_joint" type="prismatic">
        <origin xyz="-0.0132 -0.0265 0.093" rpy="0 0 1.5708" />
        <parent link="hand_base_link" />
        <child link="finger2_link" />
        <axis xyz="1 0 0" />
        <limit lower="0" upper="0.025" effort="140" velocity="1" />
        <mimic joint="finger1_joint" multiplier="1" offset="0" />
    </joint>
    <transmission name="trans_joint1">
        <type>transmission_interface/SimpleTransmission</type>
        <joint name="joint1">
            <hardwareInterface>hardware_interface/EffortJointInterface</hardwareInterface>
        </joint>
        <actuator name="joint1_motor">
            <hardwareInterface>hardware_interface/EffortJointInterface</hardwareInterface>
            <mechanicalReduction>1</mechanicalReduction>
        </actuator>
    </transmission>
    <transmission name="trans_joint2">
        <type>transmission_interface/SimpleTransmission</type>
        <joint name="joint2">
            <hardwareInterface>hardware_interface/EffortJointInterface</hardwareInterface>
        </joint>
        <actuator name="joint2_motor">
            <hardwareInterface>hardware_interface/EffortJointInterface</hardwareInterface>
            <mechanicalReduction>1</mechanicalReduction>
        </actuator>
    </transmission>
    <transmission name="trans_joint3">
        <type>transmission_interface/SimpleTransmission</type>
        <joint name="joint3">
            <hardwareInterface>hardware_interface/EffortJointInterface</hardwareInterface>
        </joint>
        <actuator name="joint3_motor">
            <hardwareInterface>hardware_interface/EffortJointInterface</hardwareInterface>
            <mechanicalReduction>1</mechanicalReduction>
        </actuator>
    </transmission>
    <transmission name="trans_joint4">
        <type>transmission_interface/SimpleTransmission</type>
        <joint name="joint4">
            <hardwareInterface>hardware_interface/EffortJointInterface</hardwareInterface>
        </joint>
        <actuator name="joint4_motor">
            <hardwareInterface>hardware_interface/EffortJointInterface</hardwareInterface>
            <mechanicalReduction>1</mechanicalReduction>
        </actuator>
    </transmission>
    <transmission name="trans_joint5">
        <type>transmission_interface/SimpleTransmission</type>
        <joint name="joint5">
            <hardwareInterface>hardware_interface/EffortJointInterface</hardwareInterface>
        </joint>
        <actuator name="joint5_motor">
            <hardwareInterface>hardware_interface/EffortJointInterface</hardwareInterface>
            <mechanicalReduction>1</mechanicalReduction>
        </actuator>
    </transmission>
    <transmission name="trans_joint6">
        <type>transmission_interface/SimpleTransmission</type>
        <joint name="joint6">
            <hardwareInterface>hardware_interface/EffortJointInterface</hardwareInterface>
        </joint>
        <actuator name="joint6_motor">
            <hardwareInterface>hardware_interface/EffortJointInterface</hardwareInterface>
            <mechanicalReduction>1</mechanicalReduction>
        </actuator>
    </transmission>
    <transmission name="trans_endeffect">
        <type>transmission_interface/SimpleTransmission</type>
        <joint name="endeffect">
            <hardwareInterface>hardware_interface/EffortJointInterface</hardwareInterface>
        </joint>
        <actuator name="endeffect_motor">
            <hardwareInterface>hardware_interface/EffortJointInterface</hardwareInterface>
            <mechanicalReduction>1</mechanicalReduction>
        </actuator>
    </transmission>
    <transmission name="trans_finger1_joint">
        <type>transmission_interface/SimpleTransmission</type>
        <joint name="finger1_joint">
            <hardwareInterface>hardware_interface/EffortJointInterface</hardwareInterface>
        </joint>
        <actuator name="finger1_joint_motor">
            <hardwareInterface>hardware_interface/EffortJointInterface</hardwareInterface>
            <mechanicalReduction>1</mechanicalReduction>
        </actuator>
    </transmission>
    <transmission name="trans_finger2_joint">
        <type>transmission_interface/SimpleTransmission</type>
        <joint name="finger2_joint">
            <hardwareInterface>hardware_interface/EffortJointInterface</hardwareInterface>
        </joint>
        <actuator name="finger2_joint_motor">
            <hardwareInterface>hardware_interface/EffortJointInterface</hardwareInterface>
            <mechanicalReduction>1</mechanicalReduction>
        </actuator>
    </transmission>
    <gazebo>
        <plugin name="gazebo_ros_control" filename="libgazebo_ros_control.so">
            <robotNamespace>/</robotNamespace>
        </plugin>
    </gazebo>
</robot>

